[2022-02-19 16:56:53,127] {taskinstance.py:1032} INFO - Dependencies all met for <TaskInstance: spark-test-cassandra-papermill.trigger_create_objects manual__2022-02-19T16:56:19.495088+00:00 [queued]>
[2022-02-19 16:56:53,145] {taskinstance.py:1032} INFO - Dependencies all met for <TaskInstance: spark-test-cassandra-papermill.trigger_create_objects manual__2022-02-19T16:56:19.495088+00:00 [queued]>
[2022-02-19 16:56:53,145] {taskinstance.py:1238} INFO - 
--------------------------------------------------------------------------------
[2022-02-19 16:56:53,145] {taskinstance.py:1239} INFO - Starting attempt 1 of 2
[2022-02-19 16:56:53,146] {taskinstance.py:1240} INFO - 
--------------------------------------------------------------------------------
[2022-02-19 16:56:53,162] {taskinstance.py:1259} INFO - Executing <Task(TriggerDagRunOperator): trigger_create_objects> on 2022-02-19 16:56:19.495088+00:00
[2022-02-19 16:56:53,168] {standard_task_runner.py:52} INFO - Started process 1200 to run task
[2022-02-19 16:56:53,171] {standard_task_runner.py:76} INFO - Running: ['***', 'tasks', 'run', 'spark-test-cassandra-papermill', 'trigger_create_objects', 'manual__2022-02-19T16:56:19.495088+00:00', '--job-id', '56', '--raw', '--subdir', 'DAGS_FOLDER/spark-cassandra-dag_withPapermill.py', '--cfg-path', '/tmp/tmpd_vyzxfh', '--error-file', '/tmp/tmpk917b0e3']
[2022-02-19 16:56:53,173] {standard_task_runner.py:77} INFO - Job 56: Subtask trigger_create_objects
[2022-02-19 16:56:53,232] {logging_mixin.py:109} INFO - Running <TaskInstance: spark-test-cassandra-papermill.trigger_create_objects manual__2022-02-19T16:56:19.495088+00:00 [running]> on host ff4bf3af9cad
[2022-02-19 16:56:53,290] {taskinstance.py:1426} INFO - Exporting the following env vars:
AIRFLOW_CTX_DAG_EMAIL=***@***.com
AIRFLOW_CTX_DAG_OWNER=***
AIRFLOW_CTX_DAG_ID=spark-test-cassandra-papermill
AIRFLOW_CTX_TASK_ID=trigger_create_objects
AIRFLOW_CTX_EXECUTION_DATE=2022-02-19T16:56:19.495088+00:00
AIRFLOW_CTX_DAG_RUN_ID=manual__2022-02-19T16:56:19.495088+00:00
[2022-02-19 16:56:54,095] {trigger_dagrun.py:145} INFO - Clearing cassandra_create_test_database_dag on 2022-02-19T00:00:00+00:00
[2022-02-19 16:56:54,243] {taskinstance.py:1700} ERROR - Task failed with exception
Traceback (most recent call last):
  File "/home/airflow/.local/lib/python3.7/site-packages/airflow/operators/trigger_dagrun.py", line 141, in execute
    replace_microseconds=False,
  File "/home/airflow/.local/lib/python3.7/site-packages/airflow/api/common/experimental/trigger_dag.py", line 125, in trigger_dag
    replace_microseconds=replace_microseconds,
  File "/home/airflow/.local/lib/python3.7/site-packages/airflow/api/common/experimental/trigger_dag.py", line 75, in _trigger_dag
    f"A Dag Run already exists for dag id {dag_id} at {execution_date} with run id {run_id}"
airflow.exceptions.DagRunAlreadyExists: A Dag Run already exists for dag id cassandra_create_test_database_dag at 2022-02-19T00:00:00+00:00 with run id manual__2022-02-19T00:00:00+00:00

During handling of the above exception, another exception occurred:

Traceback (most recent call last):
  File "/home/airflow/.local/lib/python3.7/site-packages/airflow/models/taskinstance.py", line 1329, in _run_raw_task
    self._execute_task_with_callbacks(context)
  File "/home/airflow/.local/lib/python3.7/site-packages/airflow/models/taskinstance.py", line 1455, in _execute_task_with_callbacks
    result = self._execute_task(context, self.task)
  File "/home/airflow/.local/lib/python3.7/site-packages/airflow/models/taskinstance.py", line 1511, in _execute_task
    result = execute_callable(context=context)
  File "/home/airflow/.local/lib/python3.7/site-packages/airflow/operators/trigger_dagrun.py", line 156, in execute
    dag_run = DagRun.find(dag_id=dag.dag_id, run_id=run_id)[0]
IndexError: list index out of range
[2022-02-19 16:56:54,256] {taskinstance.py:1277} INFO - Marking task as UP_FOR_RETRY. dag_id=spark-test-cassandra-papermill, task_id=trigger_create_objects, execution_date=20220219T165619, start_date=20220219T165653, end_date=20220219T165654
[2022-02-19 16:56:54,269] {standard_task_runner.py:92} ERROR - Failed to execute job 56 for task trigger_create_objects
Traceback (most recent call last):
  File "/home/airflow/.local/lib/python3.7/site-packages/airflow/operators/trigger_dagrun.py", line 141, in execute
    replace_microseconds=False,
  File "/home/airflow/.local/lib/python3.7/site-packages/airflow/api/common/experimental/trigger_dag.py", line 125, in trigger_dag
    replace_microseconds=replace_microseconds,
  File "/home/airflow/.local/lib/python3.7/site-packages/airflow/api/common/experimental/trigger_dag.py", line 75, in _trigger_dag
    f"A Dag Run already exists for dag id {dag_id} at {execution_date} with run id {run_id}"
airflow.exceptions.DagRunAlreadyExists: A Dag Run already exists for dag id cassandra_create_test_database_dag at 2022-02-19T00:00:00+00:00 with run id manual__2022-02-19T00:00:00+00:00

During handling of the above exception, another exception occurred:

Traceback (most recent call last):
  File "/home/airflow/.local/lib/python3.7/site-packages/airflow/task/task_runner/standard_task_runner.py", line 85, in _start_by_fork
    args.func(args, dag=self.dag)
  File "/home/airflow/.local/lib/python3.7/site-packages/airflow/cli/cli_parser.py", line 48, in command
    return func(*args, **kwargs)
  File "/home/airflow/.local/lib/python3.7/site-packages/airflow/utils/cli.py", line 92, in wrapper
    return f(*args, **kwargs)
  File "/home/airflow/.local/lib/python3.7/site-packages/airflow/cli/commands/task_command.py", line 298, in task_run
    _run_task_by_selected_method(args, dag, ti)
  File "/home/airflow/.local/lib/python3.7/site-packages/airflow/cli/commands/task_command.py", line 107, in _run_task_by_selected_method
    _run_raw_task(args, ti)
  File "/home/airflow/.local/lib/python3.7/site-packages/airflow/cli/commands/task_command.py", line 184, in _run_raw_task
    error_file=args.error_file,
  File "/home/airflow/.local/lib/python3.7/site-packages/airflow/utils/session.py", line 70, in wrapper
    return func(*args, session=session, **kwargs)
  File "/home/airflow/.local/lib/python3.7/site-packages/airflow/models/taskinstance.py", line 1329, in _run_raw_task
    self._execute_task_with_callbacks(context)
  File "/home/airflow/.local/lib/python3.7/site-packages/airflow/models/taskinstance.py", line 1455, in _execute_task_with_callbacks
    result = self._execute_task(context, self.task)
  File "/home/airflow/.local/lib/python3.7/site-packages/airflow/models/taskinstance.py", line 1511, in _execute_task
    result = execute_callable(context=context)
  File "/home/airflow/.local/lib/python3.7/site-packages/airflow/operators/trigger_dagrun.py", line 156, in execute
    dag_run = DagRun.find(dag_id=dag.dag_id, run_id=run_id)[0]
IndexError: list index out of range
[2022-02-19 16:56:54,306] {local_task_job.py:154} INFO - Task exited with return code 1
[2022-02-19 16:56:54,345] {local_task_job.py:264} INFO - 0 downstream tasks scheduled from follow-on schedule check
