[2022-02-19 14:41:04,718] {taskinstance.py:1032} INFO - Dependencies all met for <TaskInstance: spark-test-cassandra-papermill.trigger_config_dag scheduled__2020-01-01T00:00:00+00:00 [queued]>
[2022-02-19 14:41:04,754] {taskinstance.py:1032} INFO - Dependencies all met for <TaskInstance: spark-test-cassandra-papermill.trigger_config_dag scheduled__2020-01-01T00:00:00+00:00 [queued]>
[2022-02-19 14:41:04,754] {taskinstance.py:1238} INFO - 
--------------------------------------------------------------------------------
[2022-02-19 14:41:04,754] {taskinstance.py:1239} INFO - Starting attempt 1 of 1
[2022-02-19 14:41:04,754] {taskinstance.py:1240} INFO - 
--------------------------------------------------------------------------------
[2022-02-19 14:41:04,790] {taskinstance.py:1259} INFO - Executing <Task(TriggerDagRunOperator): trigger_config_dag> on 2020-01-01 00:00:00+00:00
[2022-02-19 14:41:04,814] {standard_task_runner.py:76} INFO - Running: ['***', 'tasks', 'run', 'spark-test-cassandra-papermill', 'trigger_config_dag', 'scheduled__2020-01-01T00:00:00+00:00', '--job-id', '9', '--raw', '--subdir', 'DAGS_FOLDER/cassandra_create_test_database.py', '--cfg-path', '/tmp/tmp86tm5k18', '--error-file', '/tmp/tmp7bvrg75v']
[2022-02-19 14:41:04,814] {standard_task_runner.py:77} INFO - Job 9: Subtask trigger_config_dag
[2022-02-19 14:41:04,814] {standard_task_runner.py:52} INFO - Started process 535 to run task
[2022-02-19 14:41:04,908] {logging_mixin.py:109} INFO - Running <TaskInstance: spark-test-cassandra-papermill.trigger_config_dag scheduled__2020-01-01T00:00:00+00:00 [running]> on host 38342be44bf7
[2022-02-19 14:41:05,040] {taskinstance.py:1426} INFO - Exporting the following env vars:
AIRFLOW_CTX_DAG_OWNER=Airflow
AIRFLOW_CTX_DAG_ID=spark-test-cassandra-papermill
AIRFLOW_CTX_TASK_ID=trigger_config_dag
AIRFLOW_CTX_EXECUTION_DATE=2020-01-01T00:00:00+00:00
AIRFLOW_CTX_DAG_RUN_ID=scheduled__2020-01-01T00:00:00+00:00
[2022-02-19 14:41:05,104] {trigger_dagrun.py:145} INFO - Clearing configuration_dag on 2020-01-01T00:00:00+00:00
[2022-02-19 14:41:05,281] {taskinstance.py:1700} ERROR - Task failed with exception
Traceback (most recent call last):
  File "/home/airflow/.local/lib/python3.7/site-packages/airflow/operators/trigger_dagrun.py", line 141, in execute
    replace_microseconds=False,
  File "/home/airflow/.local/lib/python3.7/site-packages/airflow/api/common/experimental/trigger_dag.py", line 125, in trigger_dag
    replace_microseconds=replace_microseconds,
  File "/home/airflow/.local/lib/python3.7/site-packages/airflow/api/common/experimental/trigger_dag.py", line 75, in _trigger_dag
    f"A Dag Run already exists for dag id {dag_id} at {execution_date} with run id {run_id}"
airflow.exceptions.DagRunAlreadyExists: A Dag Run already exists for dag id configuration_dag at 2020-01-01T00:00:00+00:00 with run id manual__2020-01-01T00:00:00+00:00

During handling of the above exception, another exception occurred:

Traceback (most recent call last):
  File "/home/airflow/.local/lib/python3.7/site-packages/airflow/models/taskinstance.py", line 1329, in _run_raw_task
    self._execute_task_with_callbacks(context)
  File "/home/airflow/.local/lib/python3.7/site-packages/airflow/models/taskinstance.py", line 1455, in _execute_task_with_callbacks
    result = self._execute_task(context, self.task)
  File "/home/airflow/.local/lib/python3.7/site-packages/airflow/models/taskinstance.py", line 1511, in _execute_task
    result = execute_callable(context=context)
  File "/home/airflow/.local/lib/python3.7/site-packages/airflow/operators/trigger_dagrun.py", line 156, in execute
    dag_run = DagRun.find(dag_id=dag.dag_id, run_id=run_id)[0]
IndexError: list index out of range
[2022-02-19 14:41:05,314] {taskinstance.py:1277} INFO - Marking task as FAILED. dag_id=spark-test-cassandra-papermill, task_id=trigger_config_dag, execution_date=20200101T000000, start_date=20220219T144104, end_date=20220219T144105
[2022-02-19 14:41:05,360] {standard_task_runner.py:92} ERROR - Failed to execute job 9 for task trigger_config_dag
Traceback (most recent call last):
  File "/home/airflow/.local/lib/python3.7/site-packages/airflow/operators/trigger_dagrun.py", line 141, in execute
    replace_microseconds=False,
  File "/home/airflow/.local/lib/python3.7/site-packages/airflow/api/common/experimental/trigger_dag.py", line 125, in trigger_dag
    replace_microseconds=replace_microseconds,
  File "/home/airflow/.local/lib/python3.7/site-packages/airflow/api/common/experimental/trigger_dag.py", line 75, in _trigger_dag
    f"A Dag Run already exists for dag id {dag_id} at {execution_date} with run id {run_id}"
airflow.exceptions.DagRunAlreadyExists: A Dag Run already exists for dag id configuration_dag at 2020-01-01T00:00:00+00:00 with run id manual__2020-01-01T00:00:00+00:00

During handling of the above exception, another exception occurred:

Traceback (most recent call last):
  File "/home/airflow/.local/lib/python3.7/site-packages/airflow/task/task_runner/standard_task_runner.py", line 85, in _start_by_fork
    args.func(args, dag=self.dag)
  File "/home/airflow/.local/lib/python3.7/site-packages/airflow/cli/cli_parser.py", line 48, in command
    return func(*args, **kwargs)
  File "/home/airflow/.local/lib/python3.7/site-packages/airflow/utils/cli.py", line 92, in wrapper
    return f(*args, **kwargs)
  File "/home/airflow/.local/lib/python3.7/site-packages/airflow/cli/commands/task_command.py", line 298, in task_run
    _run_task_by_selected_method(args, dag, ti)
  File "/home/airflow/.local/lib/python3.7/site-packages/airflow/cli/commands/task_command.py", line 107, in _run_task_by_selected_method
    _run_raw_task(args, ti)
  File "/home/airflow/.local/lib/python3.7/site-packages/airflow/cli/commands/task_command.py", line 184, in _run_raw_task
    error_file=args.error_file,
  File "/home/airflow/.local/lib/python3.7/site-packages/airflow/utils/session.py", line 70, in wrapper
    return func(*args, session=session, **kwargs)
  File "/home/airflow/.local/lib/python3.7/site-packages/airflow/models/taskinstance.py", line 1329, in _run_raw_task
    self._execute_task_with_callbacks(context)
  File "/home/airflow/.local/lib/python3.7/site-packages/airflow/models/taskinstance.py", line 1455, in _execute_task_with_callbacks
    result = self._execute_task(context, self.task)
  File "/home/airflow/.local/lib/python3.7/site-packages/airflow/models/taskinstance.py", line 1511, in _execute_task
    result = execute_callable(context=context)
  File "/home/airflow/.local/lib/python3.7/site-packages/airflow/operators/trigger_dagrun.py", line 156, in execute
    dag_run = DagRun.find(dag_id=dag.dag_id, run_id=run_id)[0]
IndexError: list index out of range
[2022-02-19 14:41:05,410] {local_task_job.py:154} INFO - Task exited with return code 1
[2022-02-19 14:41:05,465] {local_task_job.py:264} INFO - 0 downstream tasks scheduled from follow-on schedule check
